sdf version='1.7'>
    <model name='vehicle_blue'>
      <pose>0 0 0.325 0 -0 0</pose>
      <link name='chassis'>
        <pose>0.151427 -0 0 0 -0 0</pose>
        <inertial>
          <mass>1.14395</mass>
          <inertia>
            <ixx>0.126164</ixx>
            <ixy>0</ixy>
            <ixz>0</ixz>
            <iyy>0.416519</iyy>
            <iyz>0</iyz>
            <izz>0.481014</izz>
          </inertia>
        </inertial>
        <visual name='visual'>
          <geometry>
            <cylinder>
              <radius>0.3</radius>
              <length>0.4</length>
            </cylinder>
          </geometry>
          <material>
            <ambient>0.00588235 0.00588235 1 1</ambient>
            <diffuse>0.00588235 0.00588235 1 1</diffuse>
            <specular>0 0 1 1</specular>
          </material>
          <plugin name='__default__' filename='__default__'/>
        </visual>
        <collision name='collision'>
          <geometry>
            <box>
              <size>2.01142 1 0.568726</size>
            </box>
          </geometry>
          <surface>
            <friction>
              <ode/>
            </friction>
            <contact/>
          </surface>
        </collision>
      </link>
      <link name='left_wheel'>
        <pose>0.3 0.225029 -0.2 -1.5707 0 0</pose>
        <inertial>
          <mass>2</mass>
          <inertia>
            <ixx>0.145833</ixx>
            <ixy>0</ixy>
            <ixz>0</ixz>
            <iyy>0.145833</iyy>
            <iyz>0</iyz>
            <izz>0.125</izz>
          </inertia>
        </inertial>
        <visual name='visual'>
          <geometry>
            <sphere>
              <radius>0.1</radius>
            </sphere>
          </geometry>
          <material>
            <ambient>0.2 0.2 0.2 1</ambient>
            <diffuse>0.2 0.2 0.2 1</diffuse>
            <specular>0.2 0.2 0.2 1</specular>
          </material>
          <plugin name='__default__' filename='__default__'/>
        </visual>
        <collision name='collision'>
          <geometry>
            <sphere>
              <radius>0.1</radius>
            </sphere>
          </geometry>
          <surface>
            <friction>
              <ode/>
            </friction>
            <contact/>
          </surface>
        </collision>
      </link>
      <link name='right_wheel'>
        <pose>0.3 -0.225029 -0.2 -1.5707 0 0</pose>
        <inertial>
          <mass>2</mass>
          <inertia>
            <ixx>0.145833</ixx>
            <ixy>0</ixy>
            <ixz>0</ixz>
            <iyy>0.145833</iyy>
            <iyz>0</iyz>
            <izz>0.125</izz>
          </inertia>
        </inertial>
        <visual name='visual'>
          <geometry>
            <sphere>
              <radius>0.1</radius>
            </sphere>
          </geometry>
          <material>
            <ambient>0.2 0.2 0.2 1</ambient>
            <diffuse>0.2 0.2 0.2 1</diffuse>
            <specular>0.2 0.2 0.2 1</specular>
          </material>
          <plugin name='__default__' filename='__default__'/>
        </visual>
        <collision name='collision'>
          <geometry>
            <sphere>
              <radius>0.1</radius>
            </sphere>
          </geometry>
          <surface>
            <friction>
              <ode/>
            </friction>
            <contact/>
          </surface>
        </collision>
      </link>
      <link name='caster'>
        <pose>-0 -0 -0.2 0 -0 0</pose>
        <inertial>
          <mass>1</mass>
          <inertia>
            <ixx>0.1</ixx>
            <ixy>0</ixy>
            <ixz>0</ixz>
            <iyy>0.1</iyy>
            <iyz>0</iyz>
            <izz>0.1</izz>
          </inertia>
        </inertial>
        <visual name='visual'>
          <geometry>
            <sphere>
              <radius>0.1</radius>
            </sphere>
          </geometry>
          <material>
            <ambient>0.2 0.2 0.2 1</ambient>
            <diffuse>0.2 0.2 0.2 1</diffuse>
            <specular>0.2 0.2 0.2 1</specular>
          </material>
          <plugin name='__default__' filename='__default__'/>
        </visual>
        <collision name='collision'>
          <geometry>
            <sphere>
              <radius>0.1</radius>
            </sphere>
          </geometry>
          <surface>
            <friction>
              <ode/>
            </friction>
            <contact/>
          </surface>
        </collision>
      </link>
      <link name='lidar'>
        <pose>0.15 -0 0.25 0 -0 0</pose>
        <inertial>
          <mass>1.14395</mass>
          <inertia>
            <ixx>0.126164</ixx>
            <ixy>0</ixy>
            <ixz>0</ixz>
            <iyy>0.416519</iyy>
            <iyz>0</iyz>
            <izz>0.481014</izz>
          </inertia>
        </inertial>
        <visual name='visual'>
          <geometry>
            <box>
              <size>0.1 0.11 0.1</size>
            </box>
          </geometry>
          <material>
            <ambient>0.5 0.5 1 1</ambient>
            <diffuse>0.5 0.5 1 1</diffuse>
            <specular>0 0 1 1</specular>
          </material>
          <plugin name='__default__' filename='__default__'/>
        </visual>
        <sensor name='gpu_lidar' type='gpu_lidar'>
          <topic>lidar</topic>
          <update_rate>100</update_rate>
          <lidar>
            <scan>
              <horizontal>
                <samples>640</samples>
                <resolution>1</resolution>
                <min_angle>-3.14</min_angle>
                <max_angle>3.14</max_angle>
              </horizontal>
              <vertical>
                <samples>16</samples>
                <resolution>1</resolution>
                <min_angle>-0.261799</min_angle>
                <max_angle>0.261799</max_angle>
              </vertical>
            </scan>
            <range>
              <min>0.08</min>
              <max>10</max>
              <resolution>0.01</resolution>
            </range>
          </lidar>
          <visualize>1</visualize>
          <alwaysOn>1</alwaysOn>
          <plugin name='__default__' filename='__default__'/>
        </sensor>
      </link>
      <joint name='left_wheel_joint' type='revolute'>
        <parent>chassis</parent>
        <child>left_wheel</child>
        <axis>
          <xyz>0 0 1</xyz>
          <limit>
            <lower>-1.79769e+308</lower>
            <upper>1.79769e+308</upper>
          </limit>
        </axis>
      </joint>
      <joint name='lidar_joint' type='fixed'>
        <parent>chassis</parent>
        <child>lidar</child>
        <axis>
          <xyz>0 0 1</xyz>
          <limit>
            <lower>-1.79769e+308</lower>
            <upper>1.79769e+308</upper>
          </limit>
        </axis>
      </joint>
      <joint name='right_wheel_joint' type='revolute'>
        <parent>chassis</parent>
        <child>right_wheel</child>
        <axis>
          <xyz>0 0 1</xyz>
          <limit>
            <lower>-1.79769e+308</lower>
            <upper>1.79769e+308</upper>
          </limit>
        </axis>
      </joint>
      <joint name='caster_wheel' type='ball'>
        <parent>chassis</parent>
        <child>caster</child>
      </joint>
      <plugin name='ignition::gazebo::systems::DiffDrive' filename='ignition-gazebo-diff-drive-system'>
        <left_joint>left_wheel_joint</left_joint>
        <right_joint>right_wheel_joint</right_joint>
        <wheel_separation>0.450058</wheel_separation>
        <wheel_radius>0.1</wheel_radius>
        <odom_publish_frequency>100</odom_publish_frequency>
      </plugin>
    </model>
    <model name='box'>
      <pose>6.22648 7.47132 0.5 0 -0 0</pose>
      <link name='box_link'>
        <inertial>
          <inertia>
            <ixx>0.167</ixx>
            <ixy>0</ixy>
            <ixz>0</ixz>
            <iyy>0.167</iyy>
            <iyz>0</iyz>
            <izz>0.167</izz>
          </inertia>
          <mass>1</mass>
        </inertial>
        <collision name='box_collision'>
          <geometry>
            <box>
              <size>1 1 1</size>
            </box>
          </geometry>
          <surface>
            <friction>
              <ode/>
            </friction>
            <contact/>
          </surface>
        </collision>
        <visual name='box_visual'>
          <geometry>
            <box>
              <size>1 1 1</size>
            </box>
          </geometry>
          <plugin name='__default__' filename='__default__'/>
        </visual>
      </link>
      <plugin name='__default__' filename='__default__'/>
    </model>
    <model name='cylinder'>
      <pose>4.94461 2.56357 0.5 0 -0 0</pose>
      <link name='cylinder_link'>
        <inertial>
          <inertia>
            <ixx>0.146</ixx>
            <ixy>0</ixy>
            <ixz>0</ixz>
            <iyy>0.146</iyy>
            <iyz>0</iyz>
            <izz>0.125</izz>
          </inertia>
          <mass>1</mass>
        </inertial>
        <collision name='cylinder_collision'>
          <geometry>
            <cylinder>
              <radius>0.5</radius>
              <length>1</length>
            </cylinder>
          </geometry>
          <surface>
            <friction>
              <ode/>
            </friction>
            <contact/>
          </surface>
        </collision>
        <visual name='cylinder_visual'>
          <geometry>
            <cylinder>
              <radius>0.5</radius>
              <length>1</length>
            </cylinder>
          </geometry>
          <plugin name='__default__' filename='__default__'/>
        </visual>
      </link>
      <plugin name='__default__' filename='__default__'/>
    </model>
    <model name='cylinder_0'>
      <pose>4.7524 -7.80486 0.5 0 -0 0</pose>
      <link name='cylinder_link'>
        <inertial>
          <inertia>
            <ixx>0.146</ixx>
            <ixy>0</ixy>
            <ixz>0</ixz>
            <iyy>0.146</iyy>
            <iyz>0</iyz>
            <izz>0.125</izz>
          </inertia>
          <mass>1</mass>
        </inertial>
        <collision name='cylinder_collision'>
          <geometry>
            <cylinder>
              <radius>0.5</radius>
              <length>1</length>
            </cylinder>
          </geometry>
          <surface>
            <friction>
              <ode/>
            </friction>
            <contact/>
          </surface>
        </collision>
        <visual name='cylinder_visual'>
          <geometry>
            <cylinder>
              <radius>0.5</radius>
              <length>1</length>
            </cylinder>
          </geometry>
          <plugin name='__default__' filename='__default__'/>
        </visual>
      </link>
      <plugin name='__default__' filename='__default__'/>
    </model>
    <model name='box_0'>
      <pose>6.68117 -1.96409 0.5 0 -0 0</pose>
      <link name='box_link'>
        <inertial>
          <inertia>
            <ixx>0.167</ixx>
            <ixy>0</ixy>
            <ixz>0</ixz>
            <iyy>0.167</iyy>
            <iyz>0</iyz>
            <izz>0.167</izz>
          </inertia>
          <mass>1</mass>
        </inertial>
        <collision name='box_collision'>
          <geometry>
            <box>
              <size>1 1 1</size>
            </box>
          </geometry>
          <surface>
            <friction>
              <ode/>
            </friction>
            <contact/>
          </surface>
        </collision>
        <visual name='box_visual'>
          <geometry>
            <box>
              <size>1 1 1</size>
            </box>
          </geometry>
          <plugin name='__default__' filename='__default__'/>
        </visual>
      </link>
      <plugin name='__default__' filename='__default__'/>
    </model>
    <model name='cylinder_1'>
      <pose>-7.03618 -2.47799 0.5 0 -0 0</pose>
      <link name='cylinder_link'>
        <inertial>
          <inertia>
            <ixx>0.146</ixx>
            <ixy>0</ixy>
            <ixz>0</ixz>
            <iyy>0.146</iyy>
            <iyz>0</iyz>
            <izz>0.125</izz>
          </inertia>
          <mass>1</mass>
        </inertial>
        <collision name='cylinder_collision'>
          <geometry>
            <cylinder>
              <radius>0.5</radius>
              <length>1</length>
            </cylinder>
          </geometry>
          <surface>
            <friction>
              <ode/>
            </friction>
            <contact/>
          </surface>
        </collision>
        <visual name='cylinder_visual'>
          <geometry>
            <cylinder>
              <radius>0.5</radius>
              <length>1</length>
            </cylinder>
          </geometry>
          <plugin name='__default__' filename='__default__'/>
        </visual>
      </link>
      <plugin name='__default__' filename='__default__'/>
    </model>
    <model name='box_1'>
      <pose>-6.48596 2.53131 0.5 0 -0 0</pose>
      <link name='box_link'>
        <inertial>
          <inertia>
            <ixx>0.167</ixx>
            <ixy>0</ixy>
            <ixz>0</ixz>
            <iyy>0.167</iyy>
            <iyz>0</iyz>
            <izz>0.167</izz>
          </inertia>
          <mass>1</mass>
        </inertial>
        <collision name='box_collision'>
          <geometry>
            <box>
              <size>1 1 1</size>
            </box>
          </geometry>
          <surface>
            <friction>
              <ode/>
            </friction>
            <contact/>
          </surface>
        </collision>
        <visual name='box_visual'>
          <geometry>
            <box>
              <size>1 1 1</size>
            </box>
          </geometry>
          <plugin name='__default__' filename='__default__'/>
        </visual>
      </link>
      <plugin name='__default__' filename='__default__'/>
    </model>
    <model name='cylinder_2'>
      <pose>-4.76471 7.7141 0.5 0 -0 0</pose>
      <link name='cylinder_link'>
        <inertial>
          <inertia>
            <ixx>0.146</ixx>
            <ixy>0</ixy>
            <ixz>0</ixz>
            <iyy>0.146</iyy>
            <iyz>0</iyz>
            <izz>0.125</izz>
          </inertia>
          <mass>1</mass>
        </inertial>
        <collision name='cylinder_collision'>
          <geometry>
            <cylinder>
              <radius>0.5</radius>
              <length>1</length>
            </cylinder>
          </geometry>
          <surface>
            <friction>
              <ode/>
            </friction>
            <contact/>
          </surface>
        </collision>
        <visual name='cylinder_visual'>
          <geometry>
            <cylinder>
              <radius>0.5</radius>
              <length>1</length>
            </cylinder>
          </geometry>
          <plugin name='__default__' filename='__default__'/>
        </visual>
      </link>
      <plugin name='__default__' filename='__default__'/>
    </model>
</sdf>
