<?xml version="1.0" ?>
<!--
  Ignition Gazebo differential drive plugin demo
  Try sending commands:
    ign topic -t "/model/vehicle_blue/cmd_vel" -m ignition.msgs.Twist -p "linear: {x: 0.5}, angular: {z: 0.05}"
    ign topic -t "/model/vehicle_green/cmd_vel" -m ignition.msgs.Twist -p "linear: {x: 1.0}, angular: {z: -0.1}"
  Listen to odometry:
    ign topic -e -t /model/vehicle_blue/odometry
    ign topic -e -t /model/vehicle_green/odometry
-->
<sdf version="1.6">
  <world name="diff_drive">

    <physics name="1ms" type="ignored">
      <max_step_size>0.001</max_step_size>
      <real_time_factor>1.0</real_time_factor>
    </physics>
    <plugin
      filename="ignition-gazebo-physics-system"
      name="ignition::gazebo::systems::Physics">
    </plugin>
    <plugin
      filename="ignition-gazebo-user-commands-system"
      name="ignition::gazebo::systems::UserCommands">
    </plugin>
    <plugin
      filename="ignition-gazebo-scene-broadcaster-system"
      name="ignition::gazebo::systems::SceneBroadcaster">
    </plugin>

    <plugin
      filename="libignition-gazebo-sensors-system.so"
      name="ignition::gazebo::systems::Sensors">
      <render_engine>ogre</render_engine>
    </plugin>

    <light type="directional" name="sun">
      <cast_shadows>true</cast_shadows>
      <pose>0 0 10 0 0 0</pose>
      <diffuse>1 1 1 1</diffuse>
      <specular>0.5 0.5 0.5 1</specular>
      <attenuation>
        <range>1000</range>
        <constant>0.9</constant>
        <linear>0.01</linear>
        <quadratic>0.001</quadratic>
      </attenuation>
      <direction>-0.5 0.1 -0.9</direction>
    </light>

    <model name="ground_plane">
      <static>true</static>
      <link name="link">
        <collision name="collision">
          <geometry>
            <plane>
              <normal>0 0 1</normal>
            </plane>
          </geometry>
        </collision>
        <visual name="visual">
          <geometry>
            <plane>
              <normal>0 0 1</normal>
              <size>100 100</size>
            </plane>
          </geometry>
          <material>
            <ambient>0.8 0.8 0.8 1</ambient>
            <diffuse>0.8 0.8 0.8 1</diffuse>
            <specular>0.8 0.8 0.8 1</specular>
          </material>
        </visual>
      </link>
    </model>

    <model name="wall">
      <pose>10 0 0.5 0 0 0</pose>
      <link name="body">
        <collision name="collision1">
          <geometry>
            <box>
              <size>0.2 20 2</size>
            </box>
          </geometry>
        </collision>
        <visual name="visual1">
          <geometry>
            <box>
              <size>0.2 20 2</size>
            </box>
          </geometry>
        </visual>
      </link>
    </model>

    <model name="wall1">
      <pose>-10 0 0.5 0 0 0</pose>
      <link name="body">
        <collision name="collision1">
          <geometry>
            <box>
              <size>0.2 20 2</size>
            </box>
          </geometry>
        </collision>
        <visual name="visual1">
          <geometry>
            <box>
              <size>0.2 20 2</size>
            </box>
          </geometry>
        </visual>
      </link>
    </model>

    <model name="wall2">
      <pose>0 10 0.5 0 0 0</pose>
      <link name="body">
        <collision name="collision1">
          <geometry>
            <box>
              <size>20 0.2 2</size>
            </box>
          </geometry>
        </collision>
        <visual name="visual1">
          <geometry>
            <box>
              <size>20 0.2 2</size>
            </box>
          </geometry>
        </visual>
      </link>
    </model>

    <model name="wall3">
      <pose>0 -10 0.5 0 0 0</pose>
      <link name="body">
        <collision name="collision1">
          <geometry>
            <box>
              <size>20 0.2 2</size>
            </box>
          </geometry>
        </collision>
        <visual name="visual1">
          <geometry>
            <box>
              <size>20 0.2 2</size>
            </box>
          </geometry>
        </visual>
      </link>
    </model>

    <model name="roomwall">
      <pose>2 0 0.5 0 0 0</pose>
      <link name="body">
        <collision name="collision1">
          <geometry>
            <box>
              <size>0.2 10 2</size>
            </box>
          </geometry>
        </collision>
        <visual name="visual1">
          <geometry>
            <box>
              <size>0.2 10 2</size>
            </box>
          </geometry>
        </visual>
      </link>
    </model>

    <model name="roomwall2">
      <pose>6 0 0.5 0 0 0</pose>
      <link name="body">
        <collision name="collision1">
          <geometry>
            <box>
              <size>8 0.2 2</size>
            </box>
          </geometry>
        </collision>
        <visual name="visual1">
          <geometry>
            <box>
              <size>8 0.2 2</size>
            </box>
          </geometry>
        </visual>
      </link>
    </model>

    <model name="roomwall3">
      <pose>2 8 0.5 0 0 0</pose>
      <link name="body">
        <collision name="collision1">
          <geometry>
            <box>
              <size>0.2 4 2</size>
            </box>
          </geometry>
        </collision>
        <visual name="visual1">
          <geometry>
            <box>
              <size>0.2 4 2</size>
            </box>
          </geometry>
        </visual>
      </link>
    </model>

    <model name="roomwall4">
      <pose>2 -8 0.5 0 0 0</pose>
      <link name="body">
        <collision name="collision1">
          <geometry>
            <box>
              <size>0.2 4 2</size>
            </box>
          </geometry>
        </collision>
        <visual name="visual1">
          <geometry>
            <box>
              <size>0.2 4 2</size>
            </box>
          </geometry>
        </visual>
      </link>
    </model>

    <model name="roomwall5">
      <pose>-2 0 0.5 0 0 0</pose>
      <link name="body">
        <collision name="collision1">
          <geometry>
            <box>
              <size>0.2 16 2</size>
            </box>
          </geometry>
        </collision>
        <visual name="visual1">
          <geometry>
            <box>
              <size>0.2 16 2</size>
            </box>
          </geometry>
        </visual>
      </link>
    </model>

    <model name="roomwall6">
      <pose>-6 0 0.5 0 0 0</pose>
      <link name="body">
        <collision name="collision1">
          <geometry>
            <box>
              <size>8 0.2 2</size>
            </box>
          </geometry>
        </collision>
        <visual name="visual1">
          <geometry>
            <box>
              <size>8 0.2 2</size>
            </box>
          </geometry>
        </visual>
      </link>
    </model>

    <model name="roomwall7">
      <pose>7 5 0.5 0 0 0</pose>
      <link name="body">
        <collision name="collision1">
          <geometry>
            <box>
              <size>6 0.2 2</size>
            </box>
          </geometry>
        </collision>
        <visual name="visual1">
          <geometry>
            <box>
              <size>6 0.2 2</size>
            </box>
          </geometry>
        </visual>
      </link>
    </model>

    <model name="roomwall8">
      <pose>-7 5 0.5 0 0 0</pose>
      <link name="body">
        <collision name="collision1">
          <geometry>
            <box>
              <size>6 0.2 2</size>
            </box>
          </geometry>
        </collision>
        <visual name="visual1">
          <geometry>
            <box>
              <size>6 0.2 2</size>
            </box>
          </geometry>
        </visual>
      </link>
    </model>

    <model name="roomwall9">
      <pose>5 -5 0.5 0 0 0</pose>
      <link name="body">
        <collision name="collision1">
          <geometry>
            <box>
              <size>6 0.2 2</size>
            </box>
          </geometry>
        </collision>
        <visual name="visual1">
          <geometry>
            <box>
              <size>6 0.2 2</size>
            </box>
          </geometry>
        </visual>
      </link>
    </model>

    <model name="roomwall10">
      <pose>-5 -5 0.5 0 0 0</pose>
      <link name="body">
        <collision name="collision1">
          <geometry>
            <box>
              <size>6 0.2 2</size>
            </box>
          </geometry>
        </collision>
        <visual name="visual1">
          <geometry>
            <box>
              <size>6 0.2 2</size>
            </box>
          </geometry>
        </visual>
      </link>
    </model>

    

    <model name='vehicle_blue'>
      <pose>0 0  0.325 0 -0 0</pose>

      <link name='chassis'>
        <pose>0.151427 -0 0.00 0 -0 0</pose>
        <inertial>
          <mass>1.14395</mass>
          <inertia>
            <ixx>0.126164</ixx>
            <ixy>0</ixy>
            <ixz>0</ixz>
            <iyy>0.416519</iyy>
            <iyz>0</iyz>
            <izz>0.481014</izz>
          </inertia>
        </inertial>
        <visual name='visual'>
          <geometry>
            <!-- <box>
              <size>2.01142 1 0.568726</size>
            </box> -->
            <cylinder>
              <radius> 0.3 </radius>
              <length> 0.4 </length>
            </cylinder>
          </geometry>
          <material>
            <ambient>1.5 1.5 1.0 1</ambient>
            <diffuse>1.5 1.5 1.0 1</diffuse>
            <specular>0.0 0.0 1.0 1</specular>
          </material>
        </visual>
        <collision name='collision'>
          <geometry>
            <box>
              <size>2.01142 1 0.568726</size>
            </box>
          </geometry>
        </collision>
      </link>

      

      <link name='left_wheel'>
        <pose>0.3 0.225029 -0.2 -1.5707 0 0</pose>
        <inertial>
          <mass>2</mass>
          <inertia>
            <ixx>0.145833</ixx>
            <ixy>0</ixy>
            <ixz>0</ixz>
            <iyy>0.145833</iyy>
            <iyz>0</iyz>
            <izz>0.125</izz>
          </inertia>
        </inertial>
        <visual name='visual'>
          <geometry>
            <sphere>
              <radius>0.1</radius>
            </sphere>
          </geometry>
          <material>
            <ambient>0.2 0.2 0.2 1</ambient>
            <diffuse>0.2 0.2 0.2 1</diffuse>
            <specular>0.2 0.2 0.2 1</specular>
          </material>
        </visual>
        <collision name='collision'>
          <geometry>
            <sphere>
              <radius>0.1</radius>
            </sphere>
          </geometry>
        </collision>
      </link>

      <link name='right_wheel'>
        <pose>0.3 -0.225029 -0.2 -1.5707 0 0</pose>
        <inertial>
          <mass>2</mass>
          <inertia>
            <ixx>0.145833</ixx>
            <ixy>0</ixy>
            <ixz>0</ixz>
            <iyy>0.145833</iyy>
            <iyz>0</iyz>
            <izz>0.125</izz>
          </inertia>
        </inertial>
        <visual name='visual'>
          <geometry>
            <sphere>
              <radius>0.1</radius>
            </sphere>
          </geometry>
          <material>
            <ambient>0.2 0.2 0.2 1</ambient>
            <diffuse>0.2 0.2 0.2 1</diffuse>
            <specular>0.2 0.2 0.2 1</specular>
          </material>
        </visual>
        <collision name='collision'>
          <geometry>
            <sphere>
              <radius>0.1</radius>
            </sphere>
          </geometry>
        </collision>
      </link>

      <link name='caster'>
        <pose>-0.0 -0 -0.2 0 -0 0</pose>
        <inertial>
          <mass>1</mass>
          <inertia>
            <ixx>0.1</ixx>
            <ixy>0</ixy>
            <ixz>0</ixz>
            <iyy>0.1</iyy>
            <iyz>0</iyz>
            <izz>0.1</izz>
          </inertia>
        </inertial>
        <visual name='visual'>
          <geometry>
            <sphere>
              <radius>0.1</radius>
            </sphere>
          </geometry>
          <material>
            <ambient>0.2 0.2 0.2 1</ambient>
            <diffuse>0.2 0.2 0.2 1</diffuse>
            <specular>0.2 0.2 0.2 1</specular>
          </material>
        </visual>
        <collision name='collision'>
          <geometry>
            <sphere>
              <radius>0.1</radius>
            </sphere>
          </geometry>
        </collision>
      </link>


      <link name='lidar'>
        <pose>0.15 -0 0.25 0 -0 0</pose>
        <inertial>
          <mass>1.14395</mass>
          <inertia>
            <ixx>0.126164</ixx>
            <ixy>0</ixy>
            <ixz>0</ixz>
            <iyy>0.416519</iyy>
            <iyz>0</iyz>
            <izz>0.481014</izz>
          </inertia>
        </inertial>
        <visual name='visual'>
          <geometry>
            <box>
              <size>0.1 0.11 0.1</size>
            </box>
          </geometry>
          <material>
            <ambient>0.5 0.5 1.0 1</ambient>
            <diffuse>0.5 0.5 1.0 1</diffuse>
            <specular>0.0 0.0 1.0 1</specular>
          </material>
        </visual>
        <sensor name='gpu_lidar' type='gpu_lidar'>
          <topic>lidar</topic>
          <update_rate>100</update_rate>
          <lidar>
            <scan>
              <horizontal>
                <samples>640</samples>
                <resolution>1</resolution>
                <min_angle>-3.14</min_angle>
                <max_angle>3.14</max_angle>
              </horizontal>
              <vertical>
                <samples>16</samples>
                <resolution>1</resolution>
                <min_angle>-0.261799</min_angle>
                <max_angle>0.261799</max_angle>
              </vertical>
            </scan>
            <range>
              <min>0.08</min>
              <max>10.0</max>
              <resolution>0.01</resolution>
            </range>
          </lidar>
          <alwaysOn>1</alwaysOn>
          <visualize>true</visualize>
        </sensor>    
      </link>



      <joint name='left_wheel_joint' type='revolute'>
        <parent>chassis</parent>
        <child>left_wheel</child>
        <axis>
          <xyz>0 0 1</xyz>
          <limit>
            <lower>-1.79769e+308</lower>
            <upper>1.79769e+308</upper>
          </limit>
        </axis>
      </joint>

       <joint name='lidar_joint' type='fixed'>
        <parent>chassis</parent>
        <child>lidar</child>
        <axis>
          <xyz>0 0 1</xyz>
          <limit>
            <lower>-1.79769e+308</lower>
            <upper>1.79769e+308</upper>
          </limit>
        </axis>
      </joint>

      <joint name='right_wheel_joint' type='revolute'>
        <parent>chassis</parent>
        <child>right_wheel</child>
        <axis>
          <xyz>0 0 1</xyz>
          <limit>
            <lower>-1.79769e+308</lower>
            <upper>1.79769e+308</upper>
          </limit>
        </axis>
      </joint>

      <joint name='caster_wheel' type='ball'>
        <parent>chassis</parent>
        <child>caster</child>
      </joint>

      <plugin
        filename="ignition-gazebo-diff-drive-system"
        name="ignition::gazebo::systems::DiffDrive">
        <left_joint>left_wheel_joint</left_joint>
        <right_joint>right_wheel_joint</right_joint>
        <wheel_separation>0.450058</wheel_separation>
        <wheel_radius>0.1</wheel_radius>
        <odom_publish_frequency>100</odom_publish_frequency>
      </plugin>

    </model>

    

  </world>
</sdf>
